Workbook

Sheet کل نمونه
A1: کشش‌های تقاضا | کل نمونه
A2: QUAIDS + Mundlak CRE + S&Y + CF • ضرایب ثابت در ۱۲ سال / ۸ کوهرت • مشتق مستقیم
A4: کشش قیمتی خودی مارشالی (Own-price) | D4: کشش مخارج غذایی
A5: گروه کالایی | B5: B1 | C5: B2 | D5: B1 | E5: B2
A6: برنج | B6: -1.079 | C6: -1.0772 | D6: 1.5667 | E6: 1.6176
A7: نان و غلات | B7: -0.6691 | C7: -0.635 | D7: 0.4328 | E7: 0.3244
A8: گوشت | B8: -0.9221 | C8: -0.933 | D8: 1.2389 | E8: 1.2596
A9: لبنیات و تخم‌مرغ | B9: -0.8005 | C9: -0.7941 | D9: 0.858 | E9: 0.8334
A10: روغن و چربی | B10: -0.4679 | C10: -0.4676 | D10: 0.7302 | E10: 1.0362
A11: میوه | B11: -1.0583 | C11: -1.053 | D11: 1.3137 | E11: 1.339
A12: سبزیجات و سیب‌زمینی | B12: -0.4504 | C12: -0.4378 | D12: 0.7523 | E12: 0.6873
A13: حبوبات | B13: -0.6936 | C13: -0.7182 | D13: 0.9829 | E13: 1.2454
A14: مغزها، خشکبار و خرما | B14: -0.9634 | C14: -0.9749 | D14: 2.1994 | E14: 1.6423
A15: قند، شیرینی و تنقلات | B15: -0.5396 | C15: -0.5372 | D15: 1.0125 | E15: 0.9824
A16: نوشیدنی بدون نوشابه | B16: -0.8534 | C16: -0.8633 | D16: 0.9017 | E16: 1.0943
A17: ادویه و چاشنی | B17: -0.4186 | C17: -0.4155 | D17: 0.8366 | E17: 0.6775
A19: نقطهٔ ارزیابی: میانگین لگاریتم قیمت و مخارج، و میانگین کنترل‌ها در زیرنمونهٔ مربوط
A20: منبع: https://github.com/sinaamiri9000-collab/paneldemand/blob/eadde5b/pilot/fixed_parameter_elasticities/report.md
A22: ردیف: تقاضای گروه • ستون: قیمت گروه • قطر پررنگ: کشش خودی • سایر خانه‌ها: کشش متقاطع
A24: ماتریس کامل کشش مارشالی ۱۲×۱۲ | B1
A25: گروه تقاضا ↓ / گروه قیمت → | B25: برنج | C25: نان و غلات | D25: گوشت | E25: لبنیات و تخم‌مرغ | F25: روغن و چربی | G25: میوه | H25: سبزیجات و سیب‌زمینی | I25: حبوبات | J25: مغزها، خشکبار و خرما | K25: قند، شیرینی و تنقلات | L25: نوشیدنی بدون نوشابه | M25: ادویه و چاشنی
A26: برنج | B26: -1.0790263 | C26: 0.010404501 | D26: -0.10042988 | E26: 0.022008032 | F26: -0.036835013 | G26: -0.079160319 | H26: -0.090488868 | I26: -0.032126711 | J26: -0.013935953 | K26: -0.088280131 | L26: -0.12178201 | M26: 0.046881712
A27: نان و غلات | B27: 0.12294417 | C27: -0.66911815 | D27: 0.21577584 | E27: -0.12597382 | F27: 0.0036227915 | G27: 0.03214903 | H27: -0.090445684 | I27: 0.035890046 | J27: 0.027157774 | K27: -0.0053161493 | L27: 0.086227512 | M27: -0.043388731
A28: گوشت | B28: 0.001993696 | C28: 0.021527365 | D28: -0.922071 | E28: -0.015185375 | F28: -0.083345122 | G28: -0.0053433047 | H28: -0.090076323 | I28: -0.020592797 | J28: -0.038154085 | K28: 0.0024189551 | L28: -0.046910781 | M28: -0.044315656
A29: لبنیات و تخم‌مرغ | B29: 0.10642321 | C29: -0.17839463 | D29: 0.057864518 | E29: -0.80052178 | F29: 0.0025067687 | G29: 0.034333412 | H29: -0.1518406 | I29: 0.043841784 | J29: 0.087220172 | K29: -0.046277945 | L29: 0.10940138 | M29: -0.11810696
A30: روغن و چربی | B30: 0.021225183 | C30: -0.027547537 | D30: -0.17599829 | E30: 0.13169576 | F30: -0.46793869 | G30: -0.038540903 | H30: -0.065315912 | I30: -0.1015982 | J30: 0.059066631 | K30: -0.010627332 | L30: -0.073784643 | M30: -0.0061491296
A31: میوه | B31: -0.15941263 | C31: 0.0010840628 | D31: -0.0075153244 | E31: 0.051394867 | F31: -0.087818333 | G31: -1.0583161 | H31: 0.12112214 | I31: -0.046576588 | J31: -0.19486873 | K31: 0.054454121 | L31: -0.029347579 | M31: 0.030094567
A32: سبزیجات و سیب‌زمینی | B32: -0.010774016 | C32: -0.12851524 | D32: -0.07121932 | E32: -0.14343775 | F32: -0.0018186556 | G32: 0.051527824 | H32: -0.45042637 | I32: 0.00070944844 | J32: 0.012467064 | K32: -0.073473338 | L32: 0.061700806 | M32: -0.025203236
A33: حبوبات | B33: -0.064198288 | C33: 0.027606299 | D33: 0.046397547 | E33: 0.25616913 | F33: -0.098995619 | G33: -0.055238437 | H33: -0.11950353 | I33: -0.69362845 | J33: -0.12317023 | K33: -0.16543947 | L33: 0.03278306 | M33: 0.004538829
A34: مغزها، خشکبار و خرما | B34: -0.16611911 | C34: -0.080349187 | D34: -0.40436678 | E34: 0.088620465 | F34: 0.0001283418 | G34: -0.2332006 | H34: -0.15047086 | I34: -0.16041049 | J34: -0.96344355 | K34: -0.11164017 | L34: -0.19668607 | M34: 0.061723621
A35: قند، شیرینی و تنقلات | B35: -0.12337285 | C35: -0.062323134 | D35: 0.0086857659 | E35: -0.11181246 | F35: -0.017514682 | G35: 0.048481168 | H35: -0.10905322 | I35: -0.042237594 | J35: -0.023248754 | K35: -0.53962437 | L35: -0.060858031 | M35: -0.0024917314
A36: نوشیدنی بدون نوشابه | B36: -0.23811245 | C36: 0.17511215 | D36: -0.066404342 | E36: 0.28635766 | F36: -0.097435432 | G36: -0.026938165 | H36: 0.16804336 | I36: 0.079725328 | J36: -0.12502015 | K36: -0.19363059 | L36: -0.85338836 | M36: 0.079307783
A37: ادویه و چاشنی | B37: 0.2314259 | C37: -0.14478875 | D37: -0.17938817 | E37: -0.3502335 | F37: -0.049723706 | G37: 0.060735376 | H37: -0.11279893 | I37: -0.036681698 | J37: 0.19476005 | K37: -0.045008704 | L37: 0.019963004 | M37: -0.41863938
A40: ماتریس کامل کشش مارشالی ۱۲×۱۲ | B2
A41: گروه تقاضا ↓ / گروه قیمت → | B41: برنج | C41: نان و غلات | D41: گوشت | E41: لبنیات و تخم‌مرغ | F41: روغن و چربی | G41: میوه | H41: سبزیجات و سیب‌زمینی | I41: حبوبات | J41: مغزها، خشکبار و خرما | K41: قند، شیرینی و تنقلات | L41: نوشیدنی بدون نوشابه | M41: ادویه و چاشنی
A42: برنج | B42: -1.0771662 | C42: -0.0051044382 | D42: -0.11469262 | E42: 0.014416182 | F42: -0.034018152 | G42: -0.080985421 | H42: -0.10018323 | I42: -0.033159427 | J42: -0.013358286 | K42: -0.088229827 | L42: -0.12589758 | M42: 0.044734119
A43: نان و غلات | B43: 0.11858323 | C43: -0.63496943 | D43: 0.23718665 | E43: -0.1072285 | F43: -0.010690998 | G43: 0.033934204 | H43: -0.0745142 | I43: 0.039571011 | J43: 0.038818316 | K43: -0.0011787473 | L43: 0.092847129 | M43: -0.035315745
A44: گوشت | B44: -0.00090268309 | C44: 0.017506621 | D44: -0.93300314 | E44: -0.020527816 | F44: -0.073908909 | G44: -0.0041700432 | H44: -0.091960751 | I44: -0.020725325 | J44: -0.039238872 | K44: -0.003179425 | L44: -0.045191977 | M44: -0.045350438
A45: لبنیات و تخم‌مرغ | B45: 0.10797107 | C45: -0.16988558 | D45: 0.058118431 | E45: -0.79406079 | F45: -0.012081748 | G45: 0.034146601 | H45: -0.14607408 | I45: 0.04396874 | J45: 0.10411005 | K45: -0.050736567 | L45: 0.10858646 | M45: -0.11303693
A46: روغن و چربی | B46: 0.01452831 | C46: -0.096817646 | D46: -0.21025498 | E46: 0.073205867 | F46: -0.46764149 | G46: -0.052772311 | H46: -0.11529246 | I46: -0.11980844 | J46: 0.033375959 | K46: -0.014981653 | L46: -0.087283033 | M46: -0.021349264
...

Sheet سال 1392
A1: کشش‌های تقاضا | سال 1392
A2: QUAIDS + Mundlak CRE + S&Y + CF • ضرایب ثابت در ۱۲ سال / ۸ کوهرت • مشتق مستقیم
A4: کشش قیمتی خودی مارشالی (Own-price) | D4: کشش مخارج غذایی
A5: گروه کالایی | B5: B1 | C5: B2 | D5: B1 | E5: B2
A6: برنج | B6: -1.0737 | C6: -1.0705 | D6: 1.5787 | E6: 1.6236
A7: نان و غلات | B7: -0.6975 | C7: -0.6661 | D7: 0.5722 | E7: 0.4757
A8: گوشت | B8: -0.9093 | C8: -0.9203 | D8: 1.2305 | E8: 1.2522
A9: لبنیات و تخم‌مرغ | B9: -0.7908 | C9: -0.7842 | D9: 0.8623 | E9: 0.8357
A10: روغن و چربی | B10: -0.4878 | C10: -0.4887 | D10: 0.7323 | E10: 1.0248
A11: میوه | B11: -1.0658 | C11: -1.0593 | D11: 1.3137 | E11: 1.3377
A12: سبزیجات و سیب‌زمینی | B12: -0.417 | C12: -0.4035 | D12: 0.7036 | E12: 0.6211
A13: حبوبات | B13: -0.6823 | C13: -0.7088 | D13: 0.9442 | E13: 1.2202
A14: مغزها، خشکبار و خرما | B14: -1.0033 | C14: -1.0109 | D14: 2.153 | E14: 1.6993
A15: قند، شیرینی و تنقلات | B15: -0.4813 | C15: -0.4791 | D15: 0.9632 | E15: 0.9334
A16: نوشیدنی بدون نوشابه | B16: -0.8298 | C16: -0.8388 | D16: 0.8311 | E16: 1.0044
A17: ادویه و چاشنی | B17: -0.3724 | C17: -0.3712 | D17: 0.7801 | E17: 0.6057
A19: نقطهٔ ارزیابی: میانگین لگاریتم قیمت و مخارج، و میانگین کنترل‌ها در زیرنمونهٔ مربوط
A20: منبع: https://github.com/sinaamiri9000-collab/paneldemand/blob/eadde5b/pilot/fixed_parameter_elasticities/report.md
A22: ردیف: تقاضای گروه • ستون: قیمت گروه • قطر پررنگ: کشش خودی • سایر خانه‌ها: کشش متقاطع
A24: ماتریس کامل کشش مارشالی ۱۲×۱۲ | B1
A25: گروه تقاضا ↓ / گروه قیمت → | B25: برنج | C25: نان و غلات | D25: گوشت | E25: لبنیات و تخم‌مرغ | F25: روغن و چربی | G25: میوه | H25: سبزیجات و سیب‌زمینی | I25: حبوبات | J25: مغزها، خشکبار و خرما | K25: قند، شیرینی و تنقلات | L25: نوشیدنی بدون نوشابه | M25: ادویه و چاشنی
A26: برنج | B26: -1.0736829 | C26: -0.0019392681 | D26: -0.094024511 | E26: 0.01634109 | F26: -0.043405307 | G26: -0.074470027 | H26: -0.090799833 | I26: -0.039435701 | J26: -0.018009249 | K26: -0.081996952 | L26: -0.12016106 | M26: 0.044176843
A27: نان و غلات | B27: 0.099931055 | C27: -0.697492 | D27: 0.15896812 | E27: -0.11089098 | F27: -0.0060034244 | G27: 0.019246725 | H27: -0.079514276 | I27: 0.021625333 | J27: 0.029222406 | K27: 0.005766067 | L27: 0.065925217 | M27: -0.042351395
A28: گوشت | B28: 0.0035893463 | C28: 0.020580119 | D28: -0.9093482 | E28: -0.012715944 | F28: -0.087704585 | G28: -0.0040210913 | H28: -0.091040476 | I28: -0.020845939 | J28: -0.041430995 | K28: 0.0057802311 | L28: -0.04893143 | M28: -0.045650391
A29: لبنیات و تخم‌مرغ | B29: 0.11073572 | C29: -0.18552923 | D29: 0.05635823 | E29: -0.79076203 | F29: 0.0021920222 | G29: 0.035589165 | H29: -0.16094511 | I29: 0.045019778 | J29: 0.090633515 | K29: -0.049428727 | L29: 0.11423978 | M29: -0.12379564
A30: روغن و چربی | B30: 0.017588697 | C30: -0.017180965 | D30: -0.17321756 | E30: 0.12636325 | F30: -0.48780013 | G30: -0.037402297 | H30: -0.06314165 | I30: -0.095449191 | J30: 0.059216085 | K30: -0.012401045 | L30: -0.067889503 | M30: -0.0054568073
A31: میوه | B31: -0.16881149 | C31: 0.0033270645 | D31: -0.0030121467 | E31: 0.057154215 | F31: -0.091037104 | G31: -1.0657523 | H31: 0.13323941 | I31: -0.048430747 | J31: -0.20586663 | K31: 0.058631525 | L31: -0.02885558 | M31: 0.032500444
A32: سبزیجات و سیب‌زمینی | B32: -0.016230171 | C32: -0.12658819 | D32: -0.094796727 | E32: -0.16177114 | F32: 0.0046556221 | G32: 0.059507839 | H32: -0.41701815 | I32: 0.0047467923 | J32: 0.0097479542 | K32: -0.078675266 | L32: 0.067721705 | M32: -0.011733578
A33: حبوبات | B33: -0.069581166 | C33: 0.036317807 | D33: 0.055630198 | E33: 0.27326609 | F33: -0.09501198 | G33: -0.057407743 | H33: -0.12201936 | I33: -0.68226689 | J33: -0.12316338 | K33: -0.17358667 | L33: 0.037650379 | M33: 0.0085203432
A34: مغزها، خشکبار و خرما | B34: -0.17441861 | C34: -0.086212538 | D34: -0.35131854 | E34: 0.067170558 | F34: -0.0011293609 | G34: -0.20207716 | H34: -0.15652313 | I34: -0.13430967 | J34: -1.0032616 | K34: -0.090399044 | L34: -0.19225609 | M34: 0.024073577
A35: قند، شیرینی و تنقلات | B35: -0.13583164 | C35: -0.067126986 | D35: 0.023105248 | E35: -0.1179914 | F35: -0.015425911 | G35: 0.056881303 | H35: -0.11455303 | I35: -0.043579084 | J35: -0.026339628 | K35: -0.48126166 | L35: -0.065384625 | M35: -0.00080681608
A36: نوشیدنی بدون نوشابه | B36: -0.22804628 | C36: 0.18012106 | D36: -0.067828607 | E36: 0.27851306 | F36: -0.089270341 | G36: -0.022629207 | H36: 0.16396799 | I36: 0.070791266 | J36: -0.11064275 | K36: -0.17262543 | L36: -0.82976668 | M36: 0.063376658
A37: ادویه و چاشنی | B37: 0.24867923 | C37: -0.14618279 | D37: -0.18877181 | E37: -0.3750749 | F37: -0.045661089 | G37: 0.067754734 | H37: -0.11349477 | I37: -0.037663535 | J37: 0.21153403 | K37: -0.047588201 | L37: 0.027276385 | M37: -0.37238371
A40: ماتریس کامل کشش مارشالی ۱۲×۱۲ | B2
A41: گروه تقاضا ↓ / گروه قیمت → | B41: برنج | C41: نان و غلات | D41: گوشت | E41: لبنیات و تخم‌مرغ | F41: روغن و چربی | G41: میوه | H41: سبزیجات و سیب‌زمینی | I41: حبوبات | J41: مغزها، خشکبار و خرما | K41: قند، شیرینی و تنقلات | L41: نوشیدنی بدون نوشابه | M41: ادویه و چاشنی
A42: برنج | B42: -1.0705036 | C42: -0.018423824 | D42: -0.10571528 | E42: 0.0095629253 | F42: -0.038118057 | G42: -0.075489632 | H42: -0.1006372 | I42: -0.03963823 | J42: -0.02091608 | K42: -0.080937277 | L42: -0.12340598 | M42: 0.041656909
A43: نان و غلات | B43: 0.09595093 | C43: -0.66613274 | D43: 0.1765755 | E43: -0.094378683 | F43: -0.018614539 | G43: 0.020537035 | H43: -0.065605201 | I43: 0.025186647 | J43: 0.040728888 | K43: 0.0084406629 | L43: 0.072046117 | M43: -0.035173911
A44: گوشت | B44: 0.00075870449 | C44: 0.015889293 | D44: -0.92027752 | E44: -0.018327433 | F44: -0.077271103 | G44: -0.002610105 | H44: -0.09320738 | I44: -0.020920325 | J44: -0.043512292 | K44: 0.00016342945 | L44: -0.047072556 | M44: -0.046935137
A45: لبنیات و تخم‌مرغ | B45: 0.11200194 | C45: -0.17570066 | D45: 0.056298532 | E45: -0.78423519 | F45: -0.013161903 | G45: 0.035260828 | H45: -0.15453399 | I45: 0.045181046 | J45: 0.10884233 | K45: -0.054208981 | L45: 0.11331338 | M45: -0.11821047
A46: روغن و چربی | B46: 0.013040649 | C46: -0.089295527 | D46: -0.20157631 | E46: 0.071772804 | F46: -0.48866584 | G46: -0.050531366 | H46: -0.10975271 | I46: -0.11421784 | J46: 0.033557482 | K46: -0.014573136 | L46: -0.082603069 | M46: -0.019777942
...

Sheet سال 1393
A1: کشش‌های تقاضا | سال 1393
A2: QUAIDS + Mundlak CRE + S&Y + CF • ضرایب ثابت در ۱۲ سال / ۸ کوهرت • مشتق مستقیم
A4: کشش قیمتی خودی مارشالی (Own-price) | D4: کشش مخارج غذایی
A5: گروه کالایی | B5: B1 | C5: B2 | D5: B1 | E5: B2
A6: برنج | B6: -1.0749 | C6: -1.0725 | D6: 1.5817 | E6: 1.6301
A7: نان و غلات | B7: -0.7182 | C7: -0.6892 | D7: 0.5895 | E7: 0.5003
A8: گوشت | B8: -0.9101 | C8: -0.9211 | D8: 1.2325 | E8: 1.254
A9: لبنیات و تخم‌مرغ | B9: -0.793 | C9: -0.7866 | D9: 0.8623 | E9: 0.836
A10: روغن و چربی | B10: -0.4478 | C10: -0.4458 | D10: 0.7073 | E10: 1.0256
A11: میوه | B11: -1.05 | C11: -1.0445 | D11: 1.274 | E11: 1.3027
A12: سبزیجات و سیب‌زمینی | B12: -0.4148 | C12: -0.4022 | D12: 0.7235 | E12: 0.6509
A13: حبوبات | B13: -0.6777 | C13: -0.703 | D13: 0.9246 | E13: 1.1922
A14: مغزها، خشکبار و خرما | B14: -0.99 | C14: -0.9969 | D14: 2.1219 | E14: 1.6443
A15: قند، شیرینی و تنقلات | B15: -0.4931 | C15: -0.4905 | D15: 0.9664 | E15: 0.9323
A16: نوشیدنی بدون نوشابه | B16: -0.8301 | C16: -0.8393 | D16: 0.8379 | E16: 1.018
A17: ادویه و چاشنی | B17: -0.3922 | C17: -0.3899 | D17: 0.7943 | E17: 0.6265
A19: نقطهٔ ارزیابی: میانگین لگاریتم قیمت و مخارج، و میانگین کنترل‌ها در زیرنمونهٔ مربوط
A20: منبع: https://github.com/sinaamiri9000-collab/paneldemand/blob/eadde5b/pilot/fixed_parameter_elasticities/report.md
A22: ردیف: تقاضای گروه • ستون: قیمت گروه • قطر پررنگ: کشش خودی • سایر خانه‌ها: کشش متقاطع
A24: ماتریس کامل کشش مارشالی ۱۲×۱۲ | B1
A25: گروه تقاضا ↓ / گروه قیمت → | B25: برنج | C25: نان و غلات | D25: گوشت | E25: لبنیات و تخم‌مرغ | F25: روغن و چربی | G25: میوه | H25: سبزیجات و سیب‌زمینی | I25: حبوبات | J25: مغزها، خشکبار و خرما | K25: قند، شیرینی و تنقلات | L25: نوشیدنی بدون نوشابه | M25: ادویه و چاشنی
A26: برنج | B26: -1.0749477 | C26: -0.0053889022 | D26: -0.096452421 | E26: 0.019174132 | F26: -0.039404379 | G26: -0.078002672 | H26: -0.090017129 | I26: -0.034307265 | J26: -0.017670494 | K26: -0.084507292 | L26: -0.12111622 | M26: 0.044239715
A27: نان و غلات | B27: 0.098556448 | C27: -0.71821559 | D27: 0.15840875 | E27: -0.11068222 | F27: -0.0047983299 | G27: 0.021941634 | H27: -0.082282644 | I27: 0.023584408 | J27: 0.026721468 | K27: -0.0050861911 | L27: 0.065970677 | M27: -0.039049184
A28: گوشت | B28: 0.003149314 | C28: 0.019600198 | D28: -0.9100658 | E28: -0.012959216 | F28: -0.086289629 | G28: -0.0045182657 | H28: -0.090828937 | I28: -0.020522988 | J28: -0.041804879 | K28: 0.005316908 | L28: -0.048412578 | M28: -0.046219006
A29: لبنیات و تخم‌مرغ | B29: 0.11029668 | C29: -0.18404496 | D29: 0.05645098 | E29: -0.79299897 | F29: 0.0015300736 | G29: 0.035399776 | H29: -0.16028076 | I29: 0.04480668 | J29: 0.091278036 | K29: -0.04950276 | L29: 0.11345483 | M29: -0.12328416
A30: روغن و چربی | B30: 0.020141986 | C30: -0.015618599 | D30: -0.18576984 | E30: 0.13520424 | F30: -0.44777816 | G30: -0.039260409 | H30: -0.067509684 | I30: -0.10354226 | J30: 0.064560123 | K30: -0.013094047 | L30: -0.074785046 | M30: -0.0058391098
A31: میوه | B31: -0.16214943 | C31: 0.0065984253 | D31: -0.00012262295 | E31: 0.056878425 | F31: -0.084754155 | G31: -1.0499903 | H31: 0.12624758 | I31: -0.043518517 | J31: -0.1987379 | K31: 0.059387676 | L31: -0.028247643 | M31: 0.032962054
A32: سبزیجات و سیب‌زمینی | B32: -0.013245254 | C32: -0.12953105 | D32: -0.081383542 | E32: -0.15482628 | F32: -0.00016246346 | G32: 0.05620921 | H32: -0.41484303 | I32: 0.0018928976 | J32: 0.01394402 | K32: -0.079187481 | L32: 0.066690304 | M32: -0.02324573
A33: حبوبات | B33: -0.065544687 | C33: 0.042524644 | D33: 0.052937414 | E33: 0.26666908 | F33: -0.096844087 | G33: -0.053043016 | H33: -0.11460224 | I33: -0.6777292 | J33: -0.12653359 | K33: -0.16561434 | L33: 0.037907241 | M33: 0.0055516623
A34: مغزها، خشکبار و خرما | B34: -0.1634532 | C34: -0.08864926 | D34: -0.35458783 | E34: 0.07478319 | F34: 0.0023147238 | G34: -0.20695168 | H34: -0.14549983 | I34: -0.13831888 | J34: -0.99000164 | K34: -0.093273961 | L34: -0.1857937 | M34: 0.037864037
A35: قند، شیرینی و تنقلات | B35: -0.13574328 | C35: -0.063916122 | D35: 0.019425886 | E35: -0.11731356 | F35: -0.014325856 | G35: 0.055566685 | H35: -0.11109838 | I35: -0.043434293 | J35: -0.025845141 | K35: -0.4931307 | L35: -0.062644863 | M35: 0.00019155989
A36: نوشیدنی بدون نوشابه | B36: -0.2345985 | C36: 0.18620666 | D36: -0.069184368 | E36: 0.28585115 | F36: -0.09468341 | G36: -0.023276452 | H36: 0.16775124 | I36: 0.072921513 | J36: -0.11460941 | K36: -0.17983805 | L36: -0.83010112 | M36: 0.067498024
A37: ادویه و چاشنی | B37: 0.24086104 | C37: -0.14149497 | D37: -0.18354246 | E37: -0.36316391 | F37: -0.046963401 | G37: 0.065380025 | H37: -0.11189967 | I37: -0.036928096 | J37: 0.20470935 | K37: -0.046270643 | L37: 0.024763437 | M37: -0.39217656
A40: ماتریس کامل کشش مارشالی ۱۲×۱۲ | B2
A41: گروه تقاضا ↓ / گروه قیمت → | B41: برنج | C41: نان و غلات | D41: گوشت | E41: لبنیات و تخم‌مرغ | F41: روغن و چربی | G41: میوه | H41: سبزیجات و سیب‌زمینی | I41: حبوبات | J41: مغزها، خشکبار و خرما | K41: قند، شیرینی و تنقلات | L41: نوشیدنی بدون نوشابه | M41: ادویه و چاشنی
A42: برنج | B42: -1.0725493 | C42: -0.021978336 | D42: -0.10920917 | E42: 0.01184769 | F42: -0.034816744 | G42: -0.079460036 | H42: -0.099696424 | I42: -0.034935926 | J42: -0.01940135 | K42: -0.083810485 | L42: -0.12469327 | M42: 0.04186903
A43: نان و غلات | B43: 0.094729209 | C43: -0.68921444 | D43: 0.17499354 | E43: -0.095170636 | F43: -0.016810632 | G43: 0.023370582 | H43: -0.069391538 | I43: 0.026684392 | J43: 0.037005901 | K43: -0.0021981119 | L43: 0.071477269 | M43: -0.032240232
A44: گوشت | B44: 0.00017762842 | C44: 0.015126985 | D44: -0.92109347 | E44: -0.018480046 | F44: -0.076090888 | G44: -0.0032134223 | H44: -0.092837962 | I44: -0.020604101 | J44: -0.043491189 | K44: -0.00043730279 | L44: -0.0465789 | M44: -0.047436149
A45: لبنیات و تخم‌مرغ | B45: 0.11162188 | C45: -0.17422272 | D45: 0.056476626 | E45: -0.78661671 | F45: -0.01374538 | G45: 0.035154149 | H45: -0.15396003 | I45: 0.04490248 | J45: 0.10910327 | K45: -0.054160522 | L45: 0.11246157 | M45: -0.11771279
A46: روغن و چربی | B46: 0.01475267 | C46: -0.095927707 | D46: -0.21767811 | E46: 0.075829439 | F46: -0.44575196 | G46: -0.054185572 | H46: -0.11799559 | I46: -0.12310662 | J46: 0.036070409 | K46: -0.0155918 | L46: -0.089897105 | M46: -0.021828718
...

Sheet سال 1394
A1: کشش‌های تقاضا | سال 1394
A2: QUAIDS + Mundlak CRE + S&Y + CF • ضرایب ثابت در ۱۲ سال / ۸ کوهرت • مشتق مستقیم
A4: کشش قیمتی خودی مارشالی (Own-price) | D4: کشش مخارج غذایی
A5: گروه کالایی | B5: B1 | C5: B2 | D5: B1 | E5: B2
A6: برنج | B6: -1.079 | C6: -1.0772 | D6: 1.5628 | E6: 1.6079
A7: نان و غلات | B7: -0.7459 | C7: -0.72 | D7: 0.6245 | E7: 0.5449
A8: گوشت | B8: -0.9082 | C8: -0.9193 | D8: 1.2386 | E8: 1.2609
A9: لبنیات و تخم‌مرغ | B9: -0.7886 | C9: -0.7825 | D9: 0.8578 | E9: 0.8311
A10: روغن و چربی | B10: -0.4359 | C10: -0.4319 | D10: 0.6748 | E10: 1.0063
A11: میوه | B11: -1.0354 | C11: -1.0301 | D11: 1.2393 | E11: 1.2728
A12: سبزیجات و سیب‌زمینی | B12: -0.3446 | C12: -0.3322 | D12: 0.6902 | E12: 0.6097
A13: حبوبات | B13: -0.6799 | C13: -0.7046 | D13: 0.9134 | E13: 1.1719
A14: مغزها، خشکبار و خرما | B14: -0.9897 | C14: -0.9951 | D14: 2.1 | E14: 1.6257
A15: قند، شیرینی و تنقلات | B15: -0.4908 | C15: -0.4884 | D15: 0.989 | E15: 0.9686
A16: نوشیدنی بدون نوشابه | B16: -0.8215 | C16: -0.8305 | D16: 0.8198 | E16: 0.9986
A17: ادویه و چاشنی | B17: -0.3899 | C17: -0.3876 | D17: 0.7971 | E17: 0.6283
A19: نقطهٔ ارزیابی: میانگین لگاریتم قیمت و مخارج، و میانگین کنترل‌ها در زیرنمونهٔ مربوط
A20: منبع: https://github.com/sinaamiri9000-collab/paneldemand/blob/eadde5b/pilot/fixed_parameter_elasticities/report.md
A22: ردیف: تقاضای گروه • ستون: قیمت گروه • قطر پررنگ: کشش خودی • سایر خانه‌ها: کشش متقاطع
A24: ماتریس کامل کشش مارشالی ۱۲×۱۲ | B1
A25: گروه تقاضا ↓ / گروه قیمت → | B25: برنج | C25: نان و غلات | D25: گوشت | E25: لبنیات و تخم‌مرغ | F25: روغن و چربی | G25: میوه | H25: سبزیجات و سیب‌زمینی | I25: حبوبات | J25: مغزها، خشکبار و خرما | K25: قند، شیرینی و تنقلات | L25: نوشیدنی بدون نوشابه | M25: ادویه و چاشنی
A26: برنج | B26: -1.0790367 | C26: -0.010291117 | D26: -0.090820106 | E26: 0.019735123 | F26: -0.035818246 | G26: -0.074523604 | H26: -0.079799674 | I26: -0.035698305 | J26: -0.019416961 | K26: -0.082835671 | L26: -0.11606359 | M26: 0.043349694
A27: نان و غلات | B27: 0.094933564 | C27: -0.7458805 | D27: 0.14688902 | E27: -0.10417493 | F27: -0.004517565 | G27: 0.021429776 | H27: -0.082373805 | I27: 0.022820852 | J27: 0.025314156 | K27: -0.006717503 | L27: 0.060745321 | M27: -0.034840978
A28: گوشت | B28: 0.00042662414 | C28: 0.018433313 | D28: -0.90824454 | E28: -0.01218759 | F28: -0.08717817 | G28: -0.0048085091 | H28: -0.089207935 | I28: -0.020907377 | J28: -0.043611678 | K28: 0.0041060026 | L28: -0.048976254 | M28: -0.047434585
A29: لبنیات و تخم‌مرغ | B29: 0.11457225 | C29: -0.18756358 | D29: 0.058100023 | E29: -0.78864315 | F29: 0.0010630787 | G29: 0.036389686 | H29: -0.16607773 | I29: 0.045889225 | J29: 0.094112439 | K29: -0.049945693 | L29: 0.11599353 | M29: -0.12618143
A30: روغن و چربی | B30: 0.02959725 | C30: -0.0075309929 | D30: -0.18194463 | E30: 0.12472601 | F30: -0.43588707 | G30: -0.036622664 | H30: -0.065998399 | I30: -0.097194754 | J30: 0.066125418 | K30: -0.0094377055 | L30: -0.075867392 | M30: -0.0081255971
A31: میوه | B31: -0.15978039 | C31: 0.010830881 | D31: 0.0028681672 | E31: 0.058392193 | F31: -0.080334535 | G31: -1.035437 | H31: 0.12267729 | I31: -0.039568661 | J31: -0.19721899 | K31: 0.062008241 | L31: -0.028206493 | M31: 0.03440943
A32: سبزیجات و سیب‌زمینی | B32: -0.011821539 | C32: -0.14353889 | D32: -0.091888623 | E32: -0.17550836 | F32: -0.0015047935 | G32: 0.063224935 | H32: -0.34463101 | I32: 0.001705312 | J32: 0.016663069 | K32: -0.088224275 | L32: 0.07460509 | M32: -0.026726484
A33: حبوبات | B33: -0.058974057 | C33: 0.048659041 | D33: 0.048777927 | E33: 0.25696591 | F33: -0.096051708 | G33: -0.049761518 | H33: -0.11245744 | I33: -0.67989553 | J33: -0.12622023 | K33: -0.15699852 | L33: 0.037487487 | M33: 0.0034229487
A34: مغزها، خشکبار و خرما | B34: -0.16621075 | C34: -0.092760658 | D34: -0.34908103 | E34: 0.078269766 | F34: 0.0047806133 | G34: -0.20494723 | H34: -0.13138243 | I34: -0.13684184 | J34: -0.98965732 | K34: -0.095444888 | L34: -0.18084269 | M34: 0.039921873
A35: قند، شیرینی و تنقلات | B35: -0.13069338 | C35: -0.07124017 | D35: 0.020056233 | E35: -0.11482077 | F35: -0.016783639 | G35: 0.053923196 | H35: -0.11699181 | I35: -0.042940719 | J35: -0.028108531 | K35: -0.49078503 | L35: -0.068047126 | M35: -0.0046502985
A36: نوشیدنی بدون نوشابه | B36: -0.23248046 | C36: 0.19293946 | D36: -0.071156938 | E36: 0.28795897 | F36: -0.097095043 | G36: -0.022493809 | H36: 0.16464095 | I36: 0.071182043 | J36: -0.11272458 | K36: -0.17625118 | L36: -0.82149345 | M36: 0.064624755
A37: ادویه و چاشنی | B37: 0.24365424 | C37: -0.13946781 | D37: -0.1861818 | E37: -0.3658892 | F37: -0.047988861 | G37: 0.065481633 | H37: -0.11541577 | I37: -0.037672956 | J37: 0.20574777 | K37: -0.046299971 | L37: 0.024520769 | M37: -0.38985411
A40: ماتریس کامل کشش مارشالی ۱۲×۱۲ | B2
A41: گروه تقاضا ↓ / گروه قیمت → | B41: برنج | C41: نان و غلات | D41: گوشت | E41: لبنیات و تخم‌مرغ | F41: روغن و چربی | G41: میوه | H41: سبزیجات و سیب‌زمینی | I41: حبوبات | J41: مغزها، خشکبار و خرما | K41: قند، شیرینی و تنقلات | L41: نوشیدنی بدون نوشابه | M41: ادویه و چاشنی
A42: برنج | B42: -1.0772251 | C42: -0.026531698 | D42: -0.10274725 | E42: 0.013288323 | F42: -0.031263452 | G42: -0.075907934 | H42: -0.088402088 | I42: -0.036047767 | J42: -0.021075828 | K42: -0.082256412 | L42: -0.11947164 | M42: 0.041104451
A43: نان و غلات | B43: 0.092615706 | C43: -0.71997283 | D43: 0.16165947 | E43: -0.09054899 | F43: -0.015214626 | G43: 0.022798057 | H43: -0.071970052 | I43: 0.025645029 | J43: 0.034268358 | K43: -0.0036481075 | L43: 0.065621417 | M43: -0.02875922
A44: گوشت | B44: -0.0030867277 | C44: 0.014070088 | D44: -0.91928516 | E44: -0.017692874 | F44: -0.077092791 | G44: -0.0035249094 | H44: -0.091025629 | I44: -0.021096031 | J44: -0.045211526 | K44: -0.0018711811 | L44: -0.047230639 | M44: -0.04872606
A45: لبنیات و تخم‌مرغ | B45: 0.11626015 | C45: -0.17724895 | D45: 0.058015962 | E45: -0.78249407 | F45: -0.014529974 | G45: 0.036130527 | H45: -0.1599079 | I45: 0.045959989 | J45: 0.11214622 | K45: -0.054558654 | L45: 0.11485569 | M45: -0.12039483
A46: روغن و چربی | B46: 0.019642363 | C46: -0.094036524 | D46: -0.21527135 | E46: 0.064312975 | F46: -0.43189869 | G46: -0.052305235 | H46: -0.11255443 | I46: -0.1171697 | J46: 0.035866203 | K46: -0.013633932 | L46: -0.091098946 | M46: -0.024821494
...

Sheet سال 1395
A1: کشش‌های تقاضا | سال 1395
A2: QUAIDS + Mundlak CRE + S&Y + CF • ضرایب ثابت در ۱۲ سال / ۸ کوهرت • مشتق مستقیم
A4: کشش قیمتی خودی مارشالی (Own-price) | D4: کشش مخارج غذایی
A5: گروه کالایی | B5: B1 | C5: B2 | D5: B1 | E5: B2
A6: برنج | B6: -1.0782 | C6: -1.0761 | D6: 1.5693 | E6: 1.6156
A7: نان و غلات | B7: -0.7401 | C7: -0.7134 | D7: 0.61 | E7: 0.5287
A8: گوشت | B8: -0.9072 | C8: -0.9183 | D8: 1.2418 | E8: 1.264
A9: لبنیات و تخم‌مرغ | B9: -0.7918 | C9: -0.7856 | D9: 0.8591 | E9: 0.8327
A10: روغن و چربی | B10: -0.4045 | C10: -0.3983 | D10: 0.6605 | E10: 1.0109
A11: میوه | B11: -1.0293 | C11: -1.0241 | D11: 1.2239 | E11: 1.2588
A12: سبزیجات و سیب‌زمینی | B12: -0.3749 | C12: -0.3633 | D12: 0.7161 | E12: 0.6449
A13: حبوبات | B13: -0.7032 | C13: -0.7269 | D13: 0.9391 | E13: 1.1847
A14: مغزها، خشکبار و خرما | B14: -0.9747 | C14: -0.981 | D14: 2.074 | E14: 1.5737
A15: قند، شیرینی و تنقلات | B15: -0.5182 | C15: -0.5158 | D15: 0.9923 | E15: 0.971
A16: نوشیدنی بدون نوشابه | B16: -0.8207 | C16: -0.8296 | D16: 0.8254 | E16: 1.0114
A17: ادویه و چاشنی | B17: -0.3868 | C17: -0.385 | D17: 0.8004 | E17: 0.6303
A19: نقطهٔ ارزیابی: میانگین لگاریتم قیمت و مخارج، و میانگین کنترل‌ها در زیرنمونهٔ مربوط
A20: منبع: https://github.com/sinaamiri9000-collab/paneldemand/blob/eadde5b/pilot/fixed_parameter_elasticities/report.md
A22: ردیف: تقاضای گروه • ستون: قیمت گروه • قطر پررنگ: کشش خودی • سایر خانه‌ها: کشش متقاطع
A24: ماتریس کامل کشش مارشالی ۱۲×۱۲ | B1
A25: گروه تقاضا ↓ / گروه قیمت → | B25: برنج | C25: نان و غلات | D25: گوشت | E25: لبنیات و تخم‌مرغ | F25: روغن و چربی | G25: میوه | H25: سبزیجات و سیب‌زمینی | I25: حبوبات | J25: مغزها، خشکبار و خرما | K25: قند، شیرینی و تنقلات | L25: نوشیدنی بدون نوشابه | M25: ادویه و چاشنی
A26: برنج | B26: -1.078159 | C26: -0.0092128062 | D26: -0.090967097 | E26: 0.020201046 | F26: -0.034083386 | G26: -0.076549895 | H26: -0.08374816 | I26: -0.037642519 | J26: -0.018986344 | K26: -0.085979368 | L26: -0.11709172 | M26: 0.044809145
A27: نان و غلات | B27: 0.094544737 | C27: -0.74013654 | D27: 0.14937476 | E27: -0.10357081 | F27: -0.0052582827 | G27: 0.022288967 | H27: -0.079696081 | I27: 0.02481953 | J27: 0.02530172 | K27: -0.0041711802 | L27: 0.061232302 | M27: -0.035366536
A28: گوشت | B28: 0.0013648342 | C28: 0.018339184 | D28: -0.90724712 | E28: -0.012819822 | F28: -0.087107362 | G28: -0.0051365338 | H28: -0.09117964 | I28: -0.022081955 | J28: -0.043530129 | K28: 0.0033098472 | L28: -0.048945251 | M28: -0.047683331
A29: لبنیات و تخم‌مرغ | B29: 0.11268341 | C29: -0.18543963 | D29: 0.056960247 | E29: -0.79184604 | F29: 0.00085513742 | G29: 0.035865398 | H29: -0.16358823 | I29: 0.046172144 | J29: 0.093681194 | K29: -0.049483434 | L29: 0.11459398 | M29: -0.12520282
A30: روغن و چربی | B30: 0.028704056 | C30: -0.0092816056 | D30: -0.19532747 | E30: 0.13406581 | F30: -0.4044549 | G30: -0.038772638 | H30: -0.068520837 | I30: -0.10223846 | J30: 0.069605192 | K30: -0.008782493 | L30: -0.081701524 | M30: -0.008909132
A31: میوه | B31: -0.1559918 | C31: 0.011168529 | D31: 0.0038032516 | E31: 0.057568927 | F31: -0.077511258 | G31: -1.0292892 | H31: 0.11896217 | I31: -0.037333635 | J31: -0.19278937 | K31: 0.061830466 | L31: -0.02789094 | M31: 0.034194804
A32: سبزیجات و سیب‌زمینی | B32: -0.010899393 | C32: -0.13887248 | D32: -0.081311152 | E32: -0.16295357 | F32: -0.0039571535 | G32: 0.058424509 | H32: -0.37486153 | I32: 0.0014667699 | J32: 0.017525849 | K32: -0.083356684 | L32: 0.070139717 | M32: -0.031602475
A33: حبوبات | B33: -0.058354435 | C33: 0.041554466 | D33: 0.044758394 | E33: 0.24276097 | F33: -0.091988221 | G33: -0.048670365 | H33: -0.10867675 | I33: -0.70324902 | J33: -0.11649543 | K33: -0.15066783 | L33: 0.033353941 | M33: 0.0041830937
A34: مغزها، خشکبار و خرما | B34: -0.15276644 | C34: -0.092538511 | D34: -0.35068767 | E34: 0.085564284 | F34: 0.0061380356 | G34: -0.21035564 | H34: -0.12507333 | I34: -0.14572373 | J34: -0.97471841 | K34: -0.10045904 | L34: -0.17557402 | M34: 0.055232158
A35: قند، شیرینی و تنقلات | B35: -0.12454553 | C35: -0.067441309 | D35: 0.01795048 | E35: -0.11006104 | F35: -0.015767137 | G35: 0.050979369 | H35: -0.11115647 | I35: -0.041565561 | J35: -0.026249877 | K35: -0.51823194 | L35: -0.063923111 | M35: -0.0038570113
A36: نوشیدنی بدون نوشابه | B36: -0.2421782 | C36: 0.19793753 | D36: -0.074292412 | E36: 0.29738052 | F36: -0.10185754 | G36: -0.02349367 | H36: 0.17168119 | I36: 0.076071333 | J36: -0.11813969 | K36: -0.18354882 | L36: -0.82067257 | M36: 0.068483144
A37: ادویه و چاشنی | B37: 0.24423315 | C37: -0.14122913 | D37: -0.18837611 | E37: -0.36834585 | F37: -0.049332834 | G37: 0.065859887 | H37: -0.11548443 | I37: -0.037537064 | J37: 0.20673729 | K37: -0.046321574 | L37: 0.024100397 | M37: -0.38682712
A40: ماتریس کامل کشش مارشالی ۱۲×۱۲ | B2
A41: گروه تقاضا ↓ / گروه قیمت → | B41: برنج | C41: نان و غلات | D41: گوشت | E41: لبنیات و تخم‌مرغ | F41: روغن و چربی | G41: میوه | H41: سبزیجات و سیب‌زمینی | I41: حبوبات | J41: مغزها، خشکبار و خرما | K41: قند، شیرینی و تنقلات | L41: نوشیدنی بدون نوشابه | M41: ادویه و چاشنی
A42: برنج | B42: -1.076142 | C42: -0.025742333 | D42: -0.10314159 | E42: 0.013528774 | F42: -0.029454393 | G42: -0.078037026 | H42: -0.09277896 | I42: -0.038200589 | J42: -0.020348427 | K42: -0.08558312 | L42: -0.12048038 | M42: 0.042534176
A43: نان و غلات | B43: 0.091832121 | C43: -0.71342081 | D43: 0.16424737 | E43: -0.089665942 | F43: -0.016558333 | G43: 0.023736677 | H43: -0.068646608 | I43: 0.027963995 | J43: 0.034451802 | K43: -0.00092832696 | L43: 0.066040605 | M43: -0.02923098
A44: گوشت | B44: -0.0020162017 | C44: 0.013852057 | D44: -0.91832502 | E44: -0.018368376 | F44: -0.076783998 | G44: -0.0038429846 | H44: -0.093105742 | I44: -0.022309652 | J44: -0.045109926 | K44: -0.0027505009 | L44: -0.047085682 | M44: -0.048947051
A45: لبنیات و تخم‌مرغ | B45: 0.11429183 | C45: -0.17533449 | D45: 0.056820818 | E45: -0.78556303 | F45: -0.014737576 | G45: 0.035649734 | H45: -0.15742466 | I45: 0.046349118 | J45: 0.11158463 | K45: -0.054016009 | L45: 0.11347065 | M45: -0.11956394
A46: روغن و چربی | B46: 0.019819208 | C46: -0.10053915 | D46: -0.2299125 | E46: 0.06985413 | F46: -0.39832371 | G46: -0.055800401 | H46: -0.12010013 | I46: -0.12496513 | J46: 0.037975832 | K46: -0.014338543 | L46: -0.097149678 | M46: -0.026211639
...

Sheet سال 1396
A1: کشش‌های تقاضا | سال 1396
A2: QUAIDS + Mundlak CRE + S&Y + CF • ضرایب ثابت در ۱۲ سال / ۸ کوهرت • مشتق مستقیم
A4: کشش قیمتی خودی مارشالی (Own-price) | D4: کشش مخارج غذایی
A5: گروه کالایی | B5: B1 | C5: B2 | D5: B1 | E5: B2
A6: برنج | B6: -1.0774 | C6: -1.0754 | D6: 1.5724 | E6: 1.6195
A7: نان و غلات | B7: -0.7188 | C7: -0.6892 | D7: 0.5722 | E7: 0.4814
A8: گوشت | B8: -0.9136 | C8: -0.9244 | D8: 1.2288 | E8: 1.2492
A9: لبنیات و تخم‌مرغ | B9: -0.7897 | C9: -0.7828 | D9: 0.8579 | E9: 0.8308
A10: روغن و چربی | B10: -0.385 | C10: -0.3792 | D10: 0.6493 | E10: 1.0118
A11: میوه | B11: -1.0188 | C11: -1.0137 | D11: 1.2018 | E11: 1.242
A12: سبزیجات و سیب‌زمینی | B12: -0.4153 | C12: -0.4024 | D12: 0.7374 | E12: 0.671
A13: حبوبات | B13: -0.7045 | C13: -0.7284 | D13: 0.9392 | E13: 1.1841
A14: مغزها، خشکبار و خرما | B14: -0.9642 | C14: -0.971 | D14: 2.0386 | E14: 1.5255
A15: قند، شیرینی و تنقلات | B15: -0.5184 | C15: -0.5168 | D15: 1.0015 | E15: 0.9885
A16: نوشیدنی بدون نوشابه | B16: -0.8095 | C16: -0.819 | D16: 0.8052 | E16: 0.9951
A17: ادویه و چاشنی | B17: -0.3633 | C17: -0.3616 | D17: 0.7908 | E17: 0.6117
A19: نقطهٔ ارزیابی: میانگین لگاریتم قیمت و مخارج، و میانگین کنترل‌ها در زیرنمونهٔ مربوط
A20: منبع: https://github.com/sinaamiri9000-collab/paneldemand/blob/eadde5b/pilot/fixed_parameter_elasticities/report.md
A22: ردیف: تقاضای گروه • ستون: قیمت گروه • قطر پررنگ: کشش خودی • سایر خانه‌ها: کشش متقاطع
A24: ماتریس کامل کشش مارشالی ۱۲×۱۲ | B1
A25: گروه تقاضا ↓ / گروه قیمت → | B25: برنج | C25: نان و غلات | D25: گوشت | E25: لبنیات و تخم‌مرغ | F25: روغن و چربی | G25: میوه | H25: سبزیجات و سیب‌زمینی | I25: حبوبات | J25: مغزها، خشکبار و خرما | K25: قند، شیرینی و تنقلات | L25: نوشیدنی بدون نوشابه | M25: ادویه و چاشنی
A26: برنج | B26: -1.0774383 | C26: -0.0024095554 | D26: -0.097665534 | E26: 0.021424783 | F26: -0.033540598 | G26: -0.076555678 | H26: -0.088662284 | I26: -0.036831021 | J26: -0.018828246 | K26: -0.087786625 | L26: -0.11696216 | M26: 0.045486823
A27: نان و غلات | B27: 0.10435674 | C27: -0.71881381 | D27: 0.16939446 | E27: -0.11666148 | F27: -0.005665819 | G27: 0.024434575 | H27: -0.086766643 | I27: 0.028274064 | J27: 0.027159005 | K27: -0.0074693464 | L27: 0.067988239 | M27: -0.039641274
A28: گوشت | B28: 0.0017222642 | C28: 0.020053474 | D28: -0.91355413 | E28: -0.011931683 | F28: -0.082467709 | G28: -0.004429097 | H28: -0.088378562 | I28: -0.02103522 | J28: -0.041271054 | K28: 0.0028875913 | L28: -0.04607134 | M28: -0.045113997
A29: لبنیات و تخم‌مرغ | B29: 0.11376805 | C29: -0.18929677 | D29: 0.058822612 | E29: -0.78965021 | F29: 0.00070452723 | G29: 0.035993081 | H29: -0.16447728 | I29: 0.046802111 | J29: 0.094931124 | K29: -0.050046753 | L29: 0.11577629 | M29: -0.1269802
A30: روغن و چربی | B30: 0.028630533 | C30: -0.016626403 | D30: -0.19637588 | E30: 0.13839854 | F30: -0.38501521 | G30: -0.041071908 | H30: -0.066255599 | I30: -0.10569665 | J30: 0.072048981 | K30: -0.0082067562 | L30: -0.085443154 | M30: -0.0097843796
A31: میوه | B31: -0.15951139 | C31: 0.013532131 | D31: 0.0078037114 | E31: 0.060918146 | F31: -0.076588346 | G31: -1.0188433 | H31: 0.1211069 | I31: -0.035261319 | J31: -0.19788931 | K31: 0.066407704 | L31: -0.028735534 | M31: 0.036609494
A32: سبزیجات و سیب‌زمینی | B32: -0.010276077 | C32: -0.13283222 | D32: -0.071785015 | E32: -0.15125532 | F32: -0.0043349911 | G32: 0.053643063 | H32: -0.41533213 | I32: 0.0012531058 | J32: 0.016768183 | K32: -0.077281371 | L32: 0.06488753 | M32: -0.030944589
A33: حبوبات | B33: -0.058557855 | C33: 0.03740565 | D33: 0.047934012 | E33: 0.24155947 | F33: -0.092006081 | G33: -0.048936524 | H33: -0.10591966 | I33: -0.70453757 | J33: -0.11571215 | K33: -0.14956206 | L33: 0.032704177 | M33: 0.0039700953
A34: مغزها، خشکبار و خرما | B34: -0.14130999 | C34: -0.082770706 | D34: -0.35524024 | E34: 0.091504594 | F34: 0.006407405 | G34: -0.20997409 | H34: -0.12182588 | I34: -0.14884201 | J34: -0.96422886 | K34: -0.10245352 | L34: -0.16892531 | M34: 0.066622693
A35: قند، شیرینی و تنقلات | B35: -0.11999742 | C35: -0.070607734 | D35: 0.018764889 | E35: -0.10816958 | F35: -0.017079116 | G35: 0.050287473 | H35: -0.11528593 | I35: -0.040861887 | J35: -0.026751257 | K35: -0.51837287 | L35: -0.066528867 | M35: -0.0062409143
A36: نوشیدنی بدون نوشابه | B36: -0.24976169 | C36: 0.20052272 | D36: -0.072862135 | E36: 0.30698857 | F36: -0.10548334 | G36: -0.024034641 | H36: 0.18079014 | I36: 0.07688891 | J36: -0.12004775 | K36: -0.18519789 | L36: -0.80950234 | M36: 0.067199705
A37: ادویه و چاشنی | B37: 0.25345114 | C37: -0.14838709 | D37: -0.19390086 | E37: -0.38364571 | F37: -0.050617483 | G37: 0.068439695 | H37: -0.1169672 | I37: -0.039528662 | J37: 0.21504891 | K37: -0.048098452 | L37: 0.025717703 | M37: -0.36333127
A40: ماتریس کامل کشش مارشالی ۱۲×۱۲ | B2
A41: گروه تقاضا ↓ / گروه قیمت → | B41: برنج | C41: نان و غلات | D41: گوشت | E41: لبنیات و تخم‌مرغ | F41: روغن و چربی | G41: میوه | H41: سبزیجات و سیب‌زمینی | I41: حبوبات | J41: مغزها، خشکبار و خرما | K41: قند، شیرینی و تنقلات | L41: نوشیدنی بدون نوشابه | M41: ادویه و چاشنی
A42: برنج | B42: -1.0753614 | C42: -0.018441858 | D42: -0.11064804 | E42: 0.014713391 | F42: -0.028950522 | G42: -0.078021568 | H42: -0.097973945 | I42: -0.037512792 | J42: -0.020165202 | K42: -0.087423877 | L42: -0.12042336 | M42: 0.043221303
A43: نان و غلات | B43: 0.1011371 | C43: -0.68922254 | D43: 0.18698529 | E43: -0.10165819 | F43: -0.018479327 | G43: 0.025888281 | H43: -0.074012564 | I43: 0.031786005 | J43: 0.037617261 | K43: -0.003843731 | L43: 0.073350397 | M43: -0.032951953
A44: گوشت | B44: -0.0013551376 | C44: 0.015896141 | D44: -0.92441653 | E44: -0.017109593 | F44: -0.072439134 | G44: -0.0031414994 | H44: -0.090138629 | I44: -0.021198469 | J44: -0.042753682 | K44: -0.0028501861 | L44: -0.044195708 | M44: -0.04621384
A45: لبنیات و تخم‌مرغ | B45: 0.11555298 | C45: -0.17973442 | D45: 0.059106067 | E45: -0.78283218 | F45: -0.015172476 | G45: 0.035807603 | H45: -0.15837361 | I45: 0.047094591 | J45: 0.1133553 | K45: -0.0547353 | L45: 0.11487159 | M45: -0.12155201
A46: روغن و چربی | B46: 0.020077857 | C46: -0.10591979 | D46: -0.23584561 | E46: 0.072397653 | F46: -0.37922145 | G46: -0.057947957 | H46: -0.12302302 | I46: -0.12922787 | J46: 0.039298073 | K46: -0.01458337 | L46: -0.10055306 | M46: -0.027125509
...

Sheet سال 1397
A1: کشش‌های تقاضا | سال 1397
A2: QUAIDS + Mundlak CRE + S&Y + CF • ضرایب ثابت در ۱۲ سال / ۸ کوهرت • مشتق مستقیم
A4: کشش قیمتی خودی مارشالی (Own-price) | D4: کشش مخارج غذایی
A5: گروه کالایی | B5: B1 | C5: B2 | D5: B1 | E5: B2
A6: برنج | B6: -1.0795 | C6: -1.0784 | D6: 1.571 | E6: 1.6234
A7: نان و غلات | B7: -0.7023 | C7: -0.6741 | D7: 0.5086 | E7: 0.4153
A8: گوشت | B8: -0.9141 | C8: -0.9247 | D8: 1.2484 | E8: 1.2717
A9: لبنیات و تخم‌مرغ | B9: -0.7906 | C9: -0.7848 | D9: 0.8514 | E9: 0.8262
A10: روغن و چربی | B10: -0.438 | C10: -0.4327 | D10: 0.6707 | E10: 1.0034
A11: میوه | B11: -1.0706 | C11: -1.0648 | D11: 1.3419 | E11: 1.363
A12: سبزیجات و سیب‌زمینی | B12: -0.454 | C12: -0.4436 | D12: 0.7545 | E12: 0.692
A13: حبوبات | B13: -0.6822 | C13: -0.708 | D13: 0.9624 | E13: 1.2291
A14: مغزها، خشکبار و خرما | B14: -0.9628 | C14: -0.9749 | D14: 2.1644 | E14: 1.6175
A15: قند، شیرینی و تنقلات | B15: -0.5249 | C15: -0.5229 | D15: 1.0185 | E15: 0.9978
A16: نوشیدنی بدون نوشابه | B16: -0.8421 | C16: -0.8517 | D16: 0.8776 | E16: 1.0698
A17: ادویه و چاشنی | B17: -0.4883 | C17: -0.4871 | D17: 0.8551 | E17: 0.7247
A19: نقطهٔ ارزیابی: میانگین لگاریتم قیمت و مخارج، و میانگین کنترل‌ها در زیرنمونهٔ مربوط
A20: منبع: https://github.com/sinaamiri9000-collab/paneldemand/blob/eadde5b/pilot/fixed_parameter_elasticities/report.md
A22: ردیف: تقاضای گروه • ستون: قیمت گروه • قطر پررنگ: کشش خودی • سایر خانه‌ها: کشش متقاطع
A24: ماتریس کامل کشش مارشالی ۱۲×۱۲ | B1
A25: گروه تقاضا ↓ / گروه قیمت → | B25: برنج | C25: نان و غلات | D25: گوشت | E25: لبنیات و تخم‌مرغ | F25: روغن و چربی | G25: میوه | H25: سبزیجات و سیب‌زمینی | I25: حبوبات | J25: مغزها، خشکبار و خرما | K25: قند، شیرینی و تنقلات | L25: نوشیدنی بدون نوشابه | M25: ادویه و چاشنی
A26: برنج | B26: -1.0794604 | C26: 0.0019393428 | D26: -0.095304103 | E26: 0.025165701 | F26: -0.03481419 | G26: -0.080109884 | H26: -0.091124514 | I26: -0.029110729 | J26: -0.014328304 | K26: -0.089830895 | L26: -0.12165597 | M26: 0.042827693
A27: نان و غلات | B27: 0.11040368 | C27: -0.70233022 | D27: 0.18408391 | E27: -0.11642044 | F27: -0.00037953628 | G27: 0.027993583 | H27: -0.082227949 | I27: 0.03048945 | J27: 0.025343821 | K27: -0.0057500727 | L27: 0.075301304 | M27: -0.035926305
A28: گوشت | B28: 0.001630158 | C28: 0.020179621 | D28: -0.91408762 | E28: -0.01437913 | F28: -0.086346281 | G28: -0.0053789338 | H28: -0.094691358 | I28: -0.021115617 | J28: -0.040823487 | K28: 0.0024974258 | L28: -0.048854694 | M28: -0.04826671
A29: لبنیات و تخم‌مرغ | B29: 0.11126416 | C29: -0.18407665 | D29: 0.059224664 | E29: -0.79056265 | F29: 0.0014219607 | G29: 0.036317577 | H29: -0.15768174 | I29: 0.044935681 | J29: 0.089543718 | K29: -0.046993754 | L29: 0.11358282 | M29: -0.1214421
A30: روغن و چربی | B30: 0.028642994 | C30: -0.016671327 | D30: -0.17711508 | E30: 0.11967096 | F30: -0.43798319 | G30: -0.035480786 | H30: -0.051199165 | I30: -0.093579136 | J30: 0.061292433 | K30: -0.0075455239 | L30: -0.076038964 | M30: -0.0064709968
A31: میوه | B31: -0.16225212 | C31: -0.00072304862 | D31: -0.010374496 | E31: 0.050759952 | F31: -0.091733548 | G31: -1.070562 | H31: 0.12487489 | I31: -0.050046271 | J31: -0.19756902 | K31: 0.052643731 | L31: -0.029383973 | M31: 0.029227851
A32: سبزیجات و سیب‌زمینی | B32: -0.010076741 | C32: -0.12478996 | D32: -0.072139108 | E32: -0.14272592 | F32: -0.0030387113 | G32: 0.050812713 | H32: -0.4539541 | I32: 0.00023462102 | J32: 0.013152556 | K32: -0.072664333 | L32: 0.060954432 | M32: -0.024423381
A33: حبوبات | B33: -0.063785107 | C33: 0.035313279 | D33: 0.045100609 | E33: 0.26047045 | F33: -0.10184598 | G33: -0.054643427 | H33: -0.11747658 | I33: -0.68221508 | J33: -0.12779869 | K33: -0.16551658 | L33: 0.034503218 | M33: 0.005522841
A34: مغزها، خشکبار و خرما | B34: -0.16151969 | C34: -0.087967704 | D34: -0.38627439 | E34: 0.092755957 | F34: 0.0041317023 | G34: -0.22876347 | H34: -0.14553842 | I34: -0.15680605 | J34: -0.96280433 | K34: -0.1104734 | L34: -0.19014678 | M34: 0.058588308
A35: قند، شیرینی و تنقلات | B35: -0.12213508 | C35: -0.069589938 | D35: 0.013325522 | E35: -0.11149336 | F35: -0.018486642 | G35: 0.049207453 | H35: -0.11582702 | I35: -0.042070122 | J35: -0.025282829 | K35: -0.52493716 | L35: -0.065624242 | M35: -0.0063013103
A36: نوشیدنی بدون نوشابه | B36: -0.24126716 | C36: 0.18475576 | D36: -0.071909151 | E36: 0.2914176 | F36: -0.10075334 | G36: -0.026378045 | H36: 0.17267019 | I36: 0.078329574 | J36: -0.12429813 | K36: -0.19206957 | L36: -0.84207845 | M36: 0.078954474
A37: ادویه و چاشنی | B37: 0.20336571 | C37: -0.12743471 | D37: -0.15653747 | E37: -0.30499903 | F37: -0.046427117 | G37: 0.052671876 | H37: -0.10170269 | I37: -0.030135452 | J37: 0.17068584 | K37: -0.037765375 | L37: 0.014771712 | M37: -0.48834808
A40: ماتریس کامل کشش مارشالی ۱۲×۱۲ | B2
A41: گروه تقاضا ↓ / گروه قیمت → | B41: برنج | C41: نان و غلات | D41: گوشت | E41: لبنیات و تخم‌مرغ | F41: روغن و چربی | G41: میوه | H41: سبزیجات و سیب‌زمینی | I41: حبوبات | J41: مغزها، خشکبار و خرما | K41: قند، شیرینی و تنقلات | L41: نوشیدنی بدون نوشابه | M41: ادویه و چاشنی
A42: برنج | B42: -1.0784282 | C42: -0.013786196 | D42: -0.10880573 | E42: 0.017397793 | F42: -0.031549134 | G42: -0.081990371 | H42: -0.10096898 | I42: -0.030408851 | J42: -0.01415387 | K42: -0.089896635 | L42: -0.12572638 | M42: 0.040334828
A43: نان و غلات | B43: 0.10700734 | C43: -0.67406271 | D43: 0.20127844 | E43: -0.099934705 | F43: -0.013439597 | G43: 0.029554487 | H43: -0.067863116 | I43: 0.03369603 | J43: 0.035751554 | K43: -0.0015907695 | L43: 0.080646767 | M43: -0.028044707
A44: گوشت | B44: -0.0017952424 | C44: 0.016425798 | D44: -0.92469868 | E44: -0.019971255 | F44: -0.076796046 | G44: -0.0041835026 | H44: -0.0972354 | I44: -0.021453202 | J44: -0.042358063 | K44: -0.0035775542 | L44: -0.047289245 | M44: -0.049857203
A45: لبنیات و تخم‌مرغ | B45: 0.1127011 | C45: -0.17457919 | D45: 0.058982444 | E45: -0.78482964 | F45: -0.01379621 | G45: 0.036002648 | H45: -0.15111479 | I45: 0.044941997 | J45: 0.10681717 | K45: -0.051349802 | L45: 0.11229187 | M45: -0.1155908
A46: روغن و چربی | B46: 0.020395612 | C46: -0.096652249 | D46: -0.2119207 | E46: 0.057598201 | F46: -0.43266326 | G46: -0.051042309 | H46: -0.10546258 | I46: -0.11315777 | J46: 0.033745298 | K46: -0.012667541 | L46: -0.090971083 | M46: -0.025512406
...

Sheet سال 1398
A1: کشش‌های تقاضا | سال 1398
A2: QUAIDS + Mundlak CRE + S&Y + CF • ضرایب ثابت در ۱۲ سال / ۸ کوهرت • مشتق مستقیم
A4: کشش قیمتی خودی مارشالی (Own-price) | D4: کشش مخارج غذایی
A5: گروه کالایی | B5: B1 | C5: B2 | D5: B1 | E5: B2
A6: برنج | B6: -1.0815 | C6: -1.0806 | D6: 1.5526 | E6: 1.6033
A7: نان و غلات | B7: -0.661 | C7: -0.6324 | D7: 0.3879 | E7: 0.2816
A8: گوشت | B8: -0.9213 | C8: -0.9321 | D8: 1.2483 | E8: 1.2708
A9: لبنیات و تخم‌مرغ | B9: -0.7824 | C9: -0.7772 | D9: 0.8404 | E9: 0.8149
A10: روغن و چربی | B10: -0.4459 | C10: -0.4392 | D10: 0.685 | E10: 1.012
A11: میوه | B11: -1.0689 | C11: -1.0637 | D11: 1.3375 | E11: 1.3564
A12: سبزیجات و سیب‌زمینی | B12: -0.4998 | C12: -0.4906 | D12: 0.7784 | E12: 0.7218
A13: حبوبات | B13: -0.6743 | C13: -0.6986 | D13: 0.9846 | E13: 1.259
A14: مغزها، خشکبار و خرما | B14: -0.9724 | C14: -0.9902 | D14: 2.3249 | E14: 1.7607
A15: قند، شیرینی و تنقلات | B15: -0.5557 | C15: -0.5521 | D15: 1.0234 | E15: 0.9926
A16: نوشیدنی بدون نوشابه | B16: -0.8839 | C16: -0.8933 | D16: 0.9608 | E16: 1.1478
A17: ادویه و چاشنی | B17: -0.5033 | C17: -0.5023 | D17: 0.8754 | E17: 0.7541
A19: نقطهٔ ارزیابی: میانگین لگاریتم قیمت و مخارج، و میانگین کنترل‌ها در زیرنمونهٔ مربوط
A20: منبع: https://github.com/sinaamiri9000-collab/paneldemand/blob/eadde5b/pilot/fixed_parameter_elasticities/report.md
A22: ردیف: تقاضای گروه • ستون: قیمت گروه • قطر پررنگ: کشش خودی • سایر خانه‌ها: کشش متقاطع
A24: ماتریس کامل کشش مارشالی ۱۲×۱۲ | B1
A25: گروه تقاضا ↓ / گروه قیمت → | B25: برنج | C25: نان و غلات | D25: گوشت | E25: لبنیات و تخم‌مرغ | F25: روغن و چربی | G25: میوه | H25: سبزیجات و سیب‌زمینی | I25: حبوبات | J25: مغزها، خشکبار و خرما | K25: قند، شیرینی و تنقلات | L25: نوشیدنی بدون نوشابه | M25: ادویه و چاشنی
A26: برنج | B26: -1.0815198 | C26: 0.014593632 | D26: -0.096171826 | E26: 0.028580709 | F26: -0.03239023 | G26: -0.079427255 | H26: -0.094680983 | I26: -0.029780626 | J26: -0.011479477 | K26: -0.087799234 | L26: -0.12302043 | M26: 0.043920026
A27: نان و غلات | B27: 0.13171862 | C27: -0.6610479 | D27: 0.22899011 | E27: -0.13512646 | F27: 0.0030327186 | G27: 0.037005618 | H27: -0.084380411 | I27: 0.037065548 | J27: 0.025284198 | K27: -0.0036532368 | L27: 0.094694922 | M27: -0.040094727
A28: گوشت | B28: 0.00045597921 | C28: 0.023149029 | D28: -0.92126743 | E28: -0.013294002 | F28: -0.083885474 | G28: -0.0064887017 | H28: -0.095103002 | I28: -0.020350027 | J28: -0.037778415 | K28: 0.0013793733 | L28: -0.049380654 | M28: -0.046858089
A29: لبنیات و تخم‌مرغ | B29: 0.117817 | C29: -0.19656569 | D29: 0.064116729 | E29: -0.78242236 | F29: 0.0021637864 | G29: 0.038381166 | H29: -0.1643943 | I29: 0.047759901 | J29: 0.095100404 | K29: -0.050100496 | L29: 0.12117238 | M29: -0.12856531
A30: روغن و چربی | B30: 0.029747567 | C30: -0.027273342 | D30: -0.17272415 | E30: 0.11623894 | F30: -0.44591317 | G30: -0.034151889 | H30: -0.048226078 | I30: -0.095687976 | J30: 0.057432691 | K30: -0.007493929 | L30: -0.072340359 | M30: -0.0066475097
A31: میوه | B31: -0.15221453 | C31: -0.0025670651 | D31: -0.012784721 | E31: 0.045794601 | F31: -0.08762893 | G31: -1.0689335 | H31: 0.11550229 | I31: -0.048269664 | J31: -0.1850199 | K31: 0.047817763 | L31: -0.02825401 | M31: 0.026476685
A32: سبزیجات و سیب‌زمینی | B32: -0.0084442362 | C32: -0.11810885 | D32: -0.064704405 | E32: -0.13216303 | F32: -0.0032207819 | G32: 0.047058913 | H32: -0.49978454 | I32: -0.00045245083 | J32: 0.010543303 | K32: -0.066276388 | L32: 0.056889244 | M32: -0.022333788
A33: حبوبات | B33: -0.064939844 | C33: 0.028649214 | D33: 0.044442815 | E33: 0.26422961 | F33: -0.107595 | G33: -0.056576887 | H33: -0.12183971 | I33: -0.67430397 | J33: -0.13373177 | K33: -0.17216563 | L33: 0.035974411 | M33: 0.0043070127
A34: مغزها، خشکبار و خرما | B34: -0.19530918 | C34: -0.082504387 | D34: -0.43117655 | E34: 0.095413084 | F34: 0.005881274 | G34: -0.24882049 | H34: -0.18248384 | I34: -0.16285647 | J34: -0.97237879 | K34: -0.11943342 | L34: -0.22082188 | M34: 0.045374886
A35: قند، شیرینی و تنقلات | B35: -0.12085086 | C35: -0.059936655 | D35: 0.0055986658 | E35: -0.10832931 | F35: -0.01716032 | G35: 0.045935251 | H35: -0.10844235 | I35: -0.041282934 | J35: -0.021972299 | K35: -0.5557179 | L35: -0.060122846 | M35: -0.0035057565
A36: نوشیدنی بدون نوشابه | B36: -0.22099266 | C36: 0.15662052 | D36: -0.062060971 | E36: 0.25928739 | F36: -0.092671385 | G36: -0.026844685 | H36: 0.15708081 | I36: 0.078384227 | J36: -0.12308652 | K36: -0.19061659 | L36: -0.88388457 | M36: 0.085361354
A37: ادویه و چاشنی | B37: 0.19800957 | C37: -0.1302228 | D37: -0.15216173 | E37: -0.29679849 | F37: -0.04865256 | G37: 0.050295173 | H37: -0.10245589 | I37: -0.028913314 | J37: 0.1646496 | K37: -0.036515481 | L37: 0.012019116 | M37: -0.50334656
A40: ماتریس کامل کشش مارشالی ۱۲×۱۲ | B2
A41: گروه تقاضا ↓ / گروه قیمت → | B41: برنج | C41: نان و غلات | D41: گوشت | E41: لبنیات و تخم‌مرغ | F41: روغن و چربی | G41: میوه | H41: سبزیجات و سیب‌زمینی | I41: حبوبات | J41: مغزها، خشکبار و خرما | K41: قند، شیرینی و تنقلات | L41: نوشیدنی بدون نوشابه | M41: ادویه و چاشنی
A42: برنج | B42: -1.0806491 | C42: 0.00053889839 | D42: -0.11022454 | E42: 0.021530834 | F42: -0.029726244 | G42: -0.081470695 | H42: -0.10492391 | I42: -0.030877535 | J42: -0.010435664 | K42: -0.088155191 | L42: -0.1273193 | M42: 0.041708183
A43: نان و غلات | B43: 0.12812028 | C43: -0.63242167 | D43: 0.25002859 | E43: -0.11626224 | F43: -0.012065637 | G43: 0.039199123 | H43: -0.066502094 | I43: 0.040292598 | J43: 0.036672056 | K43: 0.0016733406 | L43: 0.10100687 | M43: -0.030987657
A44: گوشت | B44: -0.0030720748 | C44: 0.020239798 | D44: -0.93206903 | E44: -0.018566715 | F44: -0.074774089 | G44: -0.005467471 | H44: -0.097684491 | I44: -0.020598895 | J44: -0.039022515 | K44: -0.0046483717 | L44: -0.0479201 | M44: -0.048305336
A45: لبنیات و تخم‌مرغ | B45: 0.11915489 | C45: -0.18674592 | D45: 0.064009827 | E45: -0.77724979 | F45: -0.013856483 | G45: 0.038045731 | H45: -0.15680619 | I45: 0.047482407 | J45: 0.11272814 | K45: -0.054426051 | L45: 0.11952185 | M45: -0.12206477
A46: روغن و چربی | B46: 0.020263011 | C46: -0.099332544 | D46: -0.21066899 | E46: 0.057597127 | F46: -0.43920355 | G46: -0.050787168 | H46: -0.10554621 | I46: -0.11414112 | J46: 0.032515512 | K46: -0.012998101 | L46: -0.089626954 | M46: -0.025248931
...

Sheet سال 1399
A1: کشش‌های تقاضا | سال 1399
A2: QUAIDS + Mundlak CRE + S&Y + CF • ضرایب ثابت در ۱۲ سال / ۸ کوهرت • مشتق مستقیم
A4: کشش قیمتی خودی مارشالی (Own-price) | D4: کشش مخارج غذایی
A5: گروه کالایی | B5: B1 | C5: B2 | D5: B1 | E5: B2
A6: برنج | B6: -1.081 | C6: -1.0798 | D6: 1.5639 | E6: 1.6179
A7: نان و غلات | B7: -0.6591 | C7: -0.6268 | D7: 0.3793 | E7: 0.271
A8: گوشت | B8: -0.9304 | C8: -0.9408 | D8: 1.2368 | E8: 1.2577
A9: لبنیات و تخم‌مرغ | B9: -0.7969 | C9: -0.7912 | D9: 0.8503 | E9: 0.8264
A10: روغن و چربی | B10: -0.4235 | C10: -0.4166 | D10: 0.685 | E10: 1.0236
A11: میوه | B11: -1.1068 | C11: -1.101 | D11: 1.4387 | E11: 1.4455
A12: سبزیجات و سیب‌زمینی | B12: -0.4596 | C12: -0.4489 | D12: 0.7577 | E12: 0.6943
A13: حبوبات | B13: -0.7137 | C13: -0.7372 | D13: 1.0215 | E13: 1.2765
A14: مغزها، خشکبار و خرما | B14: -0.9266 | C14: -0.9497 | D14: 2.3122 | E14: 1.6512
A15: قند، شیرینی و تنقلات | B15: -0.5537 | C15: -0.5498 | D15: 1.0269 | E15: 0.9939
A16: نوشیدنی بدون نوشابه | B16: -0.892 | C16: -0.9027 | D16: 0.9832 | E16: 1.1776
A17: ادویه و چاشنی | B17: -0.4211 | C17: -0.4197 | D17: 0.8523 | E17: 0.6957
A19: نقطهٔ ارزیابی: میانگین لگاریتم قیمت و مخارج، و میانگین کنترل‌ها در زیرنمونهٔ مربوط
A20: منبع: https://github.com/sinaamiri9000-collab/paneldemand/blob/eadde5b/pilot/fixed_parameter_elasticities/report.md
A22: ردیف: تقاضای گروه • ستون: قیمت گروه • قطر پررنگ: کشش خودی • سایر خانه‌ها: کشش متقاطع
A24: ماتریس کامل کشش مارشالی ۱۲×۱۲ | B1
A25: گروه تقاضا ↓ / گروه قیمت → | B25: برنج | C25: نان و غلات | D25: گوشت | E25: لبنیات و تخم‌مرغ | F25: روغن و چربی | G25: میوه | H25: سبزیجات و سیب‌زمینی | I25: حبوبات | J25: مغزها، خشکبار و خرما | K25: قند، شیرینی و تنقلات | L25: نوشیدنی بدون نوشابه | M25: ادویه و چاشنی
A26: برنج | B26: -1.0809863 | C26: 0.013655134 | D26: -0.10627813 | E26: 0.026313468 | F26: -0.031885798 | G26: -0.081852896 | H26: -0.089856901 | I26: -0.030982885 | J26: -0.0086641346 | K26: -0.09041031 | L26: -0.1265458 | M26: 0.048750501
A27: نان و غلات | B27: 0.12823933 | C27: -0.65913587 | D27: 0.23796439 | E27: -0.12689246 | F27: 0.002701246 | G27: 0.036273703 | H27: -0.088313084 | I27: 0.041625908 | J27: 0.021924213 | K27: -0.0030869547 | L27: 0.094848857 | M27: -0.043653941
A28: گوشت | B28: 0.0015088827 | C28: 0.020770874 | D28: -0.93039945 | E28: -0.015077433 | F28: -0.078554603 | G28: -0.005944663 | H28: -0.087629183 | I28: -0.020862287 | J28: -0.034346942 | K28: 0.0014552028 | L28: -0.046707742 | M28: -0.042333554
A29: لبنیات و تخم‌مرغ | B29: 0.10779319 | C29: -0.18006986 | D29: 0.061756188 | E29: -0.79694472 | F29: 0.0016774661 | G29: 0.035510348 | H29: -0.15218687 | I29: 0.04481788 | J29: 0.08580508 | K29: -0.04552482 | L29: 0.11151509 | M29: -0.11878295
A30: روغن و چربی | B30: 0.027289579 | C30: -0.029412511 | D30: -0.17760818 | E30: 0.13108461 | F30: -0.42352536 | G30: -0.038090938 | H30: -0.061199447 | I30: -0.10058566 | J30: 0.058124619 | K30: -0.0094428475 | L30: -0.076436517 | M30: -0.0096698909
A31: میوه | B31: -0.15996267 | C31: -0.0114859 | D31: -0.023959052 | E31: 0.041493514 | F31: -0.10077256 | G31: -1.1067517 | H31: 0.1236898 | I31: -0.059665822 | J31: -0.19183962 | K31: 0.040973677 | L31: -0.029370871 | M31: 0.022738031
A32: سبزیجات و سیب‌زمینی | B32: -0.010493372 | C32: -0.12744812 | D32: -0.069152927 | E32: -0.1425191 | F32: -0.0036987159 | G32: 0.051222848 | H32: -0.45963734 | I32: 0.0012799312 | J32: 0.0098723044 | K32: -0.072236344 | L32: 0.061742866 | M32: -0.024242063
A33: حبوبات | B33: -0.063678667 | C33: 0.020212244 | D33: 0.043724622 | E33: 0.24499609 | F33: -0.098557681 | G33: -0.056085177 | H33: -0.12229159 | I33: -0.71372771 | J33: -0.11669561 | K33: -0.16454314 | L33: 0.030149416 | M33: 0.0053592666
A34: مغزها، خشکبار و خرما | B34: -0.17090806 | C34: -0.085355147 | D34: -0.47312408 | E34: 0.1132826 | F34: 0.0055225101 | G34: -0.27148783 | H34: -0.15499853 | I34: -0.19347698 | J34: -0.92656579 | K34: -0.13212949 | L34: -0.22010052 | M34: 0.093760056
A35: قند، شیرینی و تنقلات | B35: -0.12160113 | C35: -0.060685127 | D35: 0.0026058251 | E35: -0.11115065 | F35: -0.017225991 | G35: 0.04629191 | H35: -0.10768346 | I35: -0.042876573 | J35: -0.021094305 | K35: -0.55374555 | L35: -0.060279097 | M35: -0.0023172056
A36: نوشیدنی بدون نوشابه | B36: -0.22573128 | C36: 0.15722583 | D36: -0.058507475 | E36: 0.26395074 | F36: -0.094638842 | G36: -0.028875795 | H36: 0.15467097 | I36: 0.083915152 | J36: -0.12844836 | K36: -0.19839103 | L36: -0.8920477 | M36: 0.088685143
A37: ادویه و چاشنی | B37: 0.23081393 | C37: -0.14709083 | D37: -0.17992325 | E37: -0.35070315 | F37: -0.052742031 | G37: 0.059879451 | H37: -0.11523746 | I37: -0.0367788 | J37: 0.19275176 | K37: -0.045562382 | L37: 0.019124262 | M37: -0.42114733
A40: ماتریس کامل کشش مارشالی ۱۲×۱۲ | B2
A41: گروه تقاضا ↓ / گروه قیمت → | B41: برنج | C41: نان و غلات | D41: گوشت | E41: لبنیات و تخم‌مرغ | F41: روغن و چربی | G41: میوه | H41: سبزیجات و سیب‌زمینی | I41: حبوبات | J41: مغزها، خشکبار و خرما | K41: قند، شیرینی و تنقلات | L41: نوشیدنی بدون نوشابه | M41: ادویه و چاشنی
A42: برنج | B42: -1.079815 | C42: -0.0016468117 | D42: -0.12161126 | E42: 0.018266666 | F42: -0.029354537 | G42: -0.084018242 | H42: -0.099737011 | I42: -0.032575673 | J42: -0.0069166328 | K42: -0.090607242 | L42: -0.13123143 | M42: 0.046745656
A43: نان و غلات | B43: 0.12366231 | C43: -0.62682767 | D43: 0.26009912 | E43: -0.1072219 | F43: -0.012797224 | G43: 0.038238231 | H43: -0.071481751 | I43: 0.045536682 | J43: 0.03285165 | K43: 0.001509758 | L43: 0.10165199 | M43: -0.03533034
A44: گوشت | B44: -0.0014487541 | C44: 0.017246591 | D44: -0.94082916 | E44: -0.020270069 | F44: -0.069731922 | G44: -0.0049202288 | H44: -0.089726247 | I44: -0.021157612 | J44: -0.035264874 | K44: -0.0039997473 | L44: -0.045310091 | M44: -0.043447539
A45: لبنیات و تخم‌مرغ | B45: 0.10915622 | C45: -0.17127983 | D45: 0.062011403 | E45: -0.79116995 | F45: -0.013158545 | G45: 0.035261175 | H45: -0.14601387 | I45: 0.044878762 | J45: 0.10226223 | K45: -0.049853957 | L45: 0.11046942 | M45: -0.11341881
A46: روغن و چربی | B46: 0.019106778 | C46: -0.1046603 | D46: -0.22168895 | E46: 0.066910256 | F46: -0.41662503 | G46: -0.054668376 | H46: -0.11658663 | I46: -0.12224258 | J46: 0.033803261 | K46: -0.014700172 | L46: -0.094029474 | M46: -0.026219215
...

Sheet سال 1400
A1: کشش‌های تقاضا | سال 1400
A2: QUAIDS + Mundlak CRE + S&Y + CF • ضرایب ثابت در ۱۲ سال / ۸ کوهرت • مشتق مستقیم
A4: کشش قیمتی خودی مارشالی (Own-price) | D4: کشش مخارج غذایی
A5: گروه کالایی | B5: B1 | C5: B2 | D5: B1 | E5: B2
A6: برنج | B6: -1.0809 | C6: -1.0797 | D6: 1.5628 | E6: 1.6175
A7: نان و غلات | B7: -0.6127 | C7: -0.5744 | D7: 0.2643 | E7: 0.1349
A8: گوشت | B8: -0.9312 | C8: -0.9417 | D8: 1.2358 | E8: 1.2558
A9: لبنیات و تخم‌مرغ | B9: -0.8053 | C9: -0.7993 | D9: 0.8562 | E9: 0.8329
A10: روغن و چربی | B10: -0.4068 | C10: -0.3987 | D10: 0.6833 | E10: 1.031
A11: میوه | B11: -1.0524 | C11: -1.0475 | D11: 1.3053 | E11: 1.3314
A12: سبزیجات و سیب‌زمینی | B12: -0.4916 | C12: -0.4803 | D12: 0.7764 | E12: 0.7181
A13: حبوبات | B13: -0.7141 | C13: -0.7381 | D13: 1.0308 | E13: 1.288
A14: مغزها، خشکبار و خرما | B14: -0.9187 | C14: -0.9403 | D14: 2.2695 | E14: 1.6014
A15: قند، شیرینی و تنقلات | B15: -0.5663 | C15: -0.5633 | D15: 1.0354 | E15: 1.0073
A16: نوشیدنی بدون نوشابه | B16: -0.8832 | C16: -0.8939 | D16: 0.9723 | E16: 1.1737
A17: ادویه و چاشنی | B17: -0.4319 | C17: -0.4302 | D17: 0.8596 | E17: 0.7067
A19: نقطهٔ ارزیابی: میانگین لگاریتم قیمت و مخارج، و میانگین کنترل‌ها در زیرنمونهٔ مربوط
A20: منبع: https://github.com/sinaamiri9000-collab/paneldemand/blob/eadde5b/pilot/fixed_parameter_elasticities/report.md
A22: ردیف: تقاضای گروه • ستون: قیمت گروه • قطر پررنگ: کشش خودی • سایر خانه‌ها: کشش متقاطع
A24: ماتریس کامل کشش مارشالی ۱۲×۱۲ | B1
A25: گروه تقاضا ↓ / گروه قیمت → | B25: برنج | C25: نان و غلات | D25: گوشت | E25: لبنیات و تخم‌مرغ | F25: روغن و چربی | G25: میوه | H25: سبزیجات و سیب‌زمینی | I25: حبوبات | J25: مغزها، خشکبار و خرما | K25: قند، شیرینی و تنقلات | L25: نوشیدنی بدون نوشابه | M25: ادویه و چاشنی
A26: برنج | B26: -1.0809389 | C26: 0.021722309 | D26: -0.10711609 | E26: 0.024637831 | F26: -0.030786781 | G26: -0.082319718 | H26: -0.093943023 | I26: -0.030299306 | J26: -0.0097025632 | K26: -0.092159976 | L26: -0.1250506 | M26: 0.048642309
A27: نان و غلات | B27: 0.15113591 | C27: -0.61269133 | D27: 0.28412739 | E27: -0.14695035 | F27: 0.0047858362 | G27: 0.044389648 | H27: -0.099732469 | I27: 0.051307281 | J27: 0.025313349 | K27: -0.0077145007 | L27: 0.11153491 | M27: -0.049950293
A28: گوشت | B28: 0.0016436852 | C28: 0.023592896 | D28: -0.93120086 | E28: -0.016299461 | F28: -0.077681022 | G28: -0.0059236871 | H28: -0.088832099 | I28: -0.020799516 | J28: -0.034346743 | K28: 0.00074065879 | L28: -0.045516665 | M28: -0.042357126
A29: لبنیات و تخم‌مرغ | B29: 0.10343073 | C29: -0.17502467 | D29: 0.05929999 | E29: -0.80533754 | F29: 0.0016675767 | G29: 0.033825277 | H29: -0.145259 | I29: 0.043378176 | J29: 0.083615497 | K29: -0.043996471 | L29: 0.10683071 | M29: -0.11443883
A30: روغن و چربی | B30: 0.026923666 | C30: -0.03909063 | D30: -0.18481616 | E30: 0.14030735 | F30: -0.40684565 | G30: -0.040156897 | H30: -0.061504489 | I30: -0.10613333 | J30: 0.061315469 | K30: -0.0089398213 | L30: -0.081282646 | M30: -0.009062868
A31: میوه | B31: -0.15307624 | C31: 0.00044162492 | D31: -0.0089876829 | E31: 0.04828061 | F31: -0.084641477 | G31: -1.0523754 | H31: 0.1137328 | I31: -0.044606576 | J31: -0.18717486 | K31: 0.052343399 | L31: -0.029209945 | M31: 0.028895404
